Traceback (most recent call last):
  File "c:\users\fatin\appdata\local\programs\python\python39\lib\site-packages\jupyter_cache\executors\utils.py", line 51, in single_nb_execution
    executenb(
  File "C:\Users\Fatin\AppData\Roaming\Python\Python39\site-packages\nbclient\client.py", line 1117, in execute
    return NotebookClient(nb=nb, resources=resources, km=km, **kwargs).execute()
  File "C:\Users\Fatin\AppData\Roaming\Python\Python39\site-packages\nbclient\util.py", line 78, in wrapped
    return just_run(coro(*args, **kwargs))
  File "C:\Users\Fatin\AppData\Roaming\Python\Python39\site-packages\nbclient\util.py", line 57, in just_run
    return loop.run_until_complete(coro)
  File "c:\users\fatin\appdata\local\programs\python\python39\lib\asyncio\base_events.py", line 642, in run_until_complete
    return future.result()
  File "C:\Users\Fatin\AppData\Roaming\Python\Python39\site-packages\nbclient\client.py", line 558, in async_execute
    await self.async_execute_cell(
  File "C:\Users\Fatin\AppData\Roaming\Python\Python39\site-packages\nbclient\client.py", line 862, in async_execute_cell
    self._check_raise_for_error(cell, exec_reply)
  File "C:\Users\Fatin\AppData\Roaming\Python\Python39\site-packages\nbclient\client.py", line 765, in _check_raise_for_error
    raise CellExecutionError.from_cell_and_msg(cell, exec_reply_content)
nbclient.exceptions.CellExecutionError: An error occurred while executing the following cell:
------------------
from wordcloud import WordCloud
# Generate a word cloud image for given topic
def draw_word_cloud(index):
  imp_words_topic=""
  comp=lda_model.components_[index]
  vocab_comp = zip(vocab, comp)
  sorted_words = sorted(vocab_comp, key= lambda x:x[1], reverse=True)[:50]
  for word in sorted_words:
    imp_words_topic=imp_words_topic+" "+word[0]

  wordcloud = WordCloud(width=600, height=400).generate(imp_words_topic)
  plt.figure( figsize=(5,5))
  plt.imshow(wordcloud)
  plt.axis("off")
  plt.tight_layout()
  plt.show()
 
------------------

[1;31m---------------------------------------------------------------------------[0m
[1;31mModuleNotFoundError[0m                       Traceback (most recent call last)
[1;32m~\AppData\Local\Temp/ipykernel_11092/1754887305.py[0m in [0;36m<module>[1;34m[0m
[1;32m----> 1[1;33m [1;32mfrom[0m [0mwordcloud[0m [1;32mimport[0m [0mWordCloud[0m[1;33m[0m[1;33m[0m[0m
[0m[0;32m      2[0m [1;31m# Generate a word cloud image for given topic[0m[1;33m[0m[1;33m[0m[1;33m[0m[0m
[0;32m      3[0m [1;32mdef[0m [0mdraw_word_cloud[0m[1;33m([0m[0mindex[0m[1;33m)[0m[1;33m:[0m[1;33m[0m[1;33m[0m[0m
[0;32m      4[0m   [0mimp_words_topic[0m[1;33m=[0m[1;34m""[0m[1;33m[0m[1;33m[0m[0m
[0;32m      5[0m   [0mcomp[0m[1;33m=[0m[0mlda_model[0m[1;33m.[0m[0mcomponents_[0m[1;33m[[0m[0mindex[0m[1;33m][0m[1;33m[0m[1;33m[0m[0m

[1;31mModuleNotFoundError[0m: No module named 'wordcloud'
ModuleNotFoundError: No module named 'wordcloud'

